Workbook
Name Slicer_App_Payment: #N/A
Name Slicer_Due_Date__Month: #N/A
Name Slicer_Due_Date__Year: #N/A
Name Slicer_Due_Date__Year1: #N/A
Name Slicer_Due_Date__Year2: #N/A
Name Slicer_Due_Date__Year3: #N/A
Name Slicer_Payment_Code: #N/A

Sheet Apr22
A2: Homepro | B2: 44658 | D2: Total | E2: G | F2: N | H2: F Amount | I2: Per Month | J2: Dif INT
A3: 44618 | B3: HOME PRODUCT CENTER - PETCHKASEM | D3: 193.03 | E3: =D3/2 -> 96.515 | F3: =E3 -> 96.515
A4: 44619 | B4: BONCHON CHICKEN-SP001 BANGKOK TH | D4: 775 | E4: =D4/2 -> 387.5 | F4: =E4 -> 387.5
A5: 44558 | B5: RENTOKIL INITIAL | C5: 003/006 | D5: 3564.88 | E5: =D5/2 -> 1782.44 | F5: =E5 -> 1782.44
A6: 44611 | B6: Shoppee Pay | C6: 002/010 | D6: 1590 | E6: 1590
A7: 44611 | B7: ODP-SEACON | C7: 001/003 | D7: 512.24 | E7: 512.24 | F7: 0 | H7: 1510 | I7: =H7/3 -> 503.33333 | J7: =D7-I7 -> 8.9066667
A8: 44611 | B8: ODP-SEACON | C8: 001/003 | D8: 736.14 | E8: =J8/2 -> 6.4033333 | F8: =D8-E8 -> 729.73667 | H8: 2170 | I8: =H8/3 -> 723.33333 | J8: =D8-I8 -> 12.806667
A9: 44611 | B9: MI-SHOP SEACON | C9: 001/003 | D9: 2035.06 | E9: =J9/2 -> 17.696667 | F9: =D9-E9 -> 2017.3633 | H9: 5999 | I9: =H9/3 -> 1999.6667 | J9: =D9-I9 -> 35.393333
A10: Total HomePro | D10: =SUM(D3:D9) -> 9406.35 | E10: =SUM(E3:E9) -> 4392.795 | F10: =SUM(F3:F9) -> 5013.555
A12: K-Credit | B12: 44652 | D12: Total | E12: G | F12: N
A13: 44612 | B13: True I Service | D13: 854.93 | E13: =D13 -> 854.93
A14: 44612 | B14: True I Service | D14: 1603.93 | E14: =D14 -> 1603.93
A15: 44637 | B15: Shoppee Pay | C15: 007/010 | D15: 319 | E15: =D15 -> 319
A16: 44637 | B16: Shoppee Pay | C16: 002/010 | D16: 320 | E16: =D16 -> 320
A17: 44637 | B17: Cash Back | D17: -7.74 | E17: =D17 -> -7.74
A18: Total K-Credit | D18: =SUM(D11:D17) -> 3090.12 | E18: =SUM(E11:E17) -> 3090.12 | F18: =SUM(F11:F17) -> 0
A20: KTC-Credit | B20: 44653 | D20: Total | E20: G | F20: N
A21: 44613 | B21: KTAXA Insurance | D21: 1191.87 | E21: =D21 -> 1191.87
A22: 44616 | B22: KT AXA PG | C22: 006/006 | D22: 4601.16 | E22: =D22 -> 4601.16 | H22: =D22*6 -> 27606.96
A23: 44616 | B23: KT AXA PG-INT-0.74% | C23: 006/006 | D23: 204.29 | E23: =D23 -> 204.29 | H23: =D23*6 -> 1225.74
E25: =D25 -> 0
A26: Total KTC-Credit | D26: =SUM(D21:D25) -> 5997.32 | E26: =SUM(E19:E25) -> 5997.32 | F26: =SUM(F19:F25) -> 0
A28: AEON-Big C Credit | B28: 44653 | D28: Total | E28: G | F28: N
A29: 44618 | B29: BIG C- Petkasem | D29: 3452 | E29: =2137+237 -> 2374 | F29: 1078
A30: 44602 | B30: MINI BIG C- BCP Kanlapap | D30: 148 | E30: 74 | F30: 74
A34: Total AEON-Big C-Credit | D34: =SUM(D29:D33) -> 3600 | E34: =SUM(E27:E33) -> 2448 | F34: =SUM(F27:F33) -> 1152
A36: The1-Credit | B36: 44673 | D36: Total | E36: G | F36: N
A37: 44622 | B37: Steam Purchase | D37: 528.42 | E37: =D37 -> 528.42
A38: 44623 | B38: NetFLIX | D38: 419 | E38: 219 | F38: 200
A39: 44626 | B39: Sizler-Seacon | D39: 729 | E39: =D39/2 -> 364.5 | F39: =E39 -> 364.5
A40: 44634 | B40: DLT E-PAY ภาษีรถยนต์ | D40: 1064.71 | E40: =D40/2 -> 532.355 | F40: =E40 -> 532.355
A41: 44636 | B41: Steamgame.com 4259522 | D41: 284.7 | E41: =D41 -> 284.7
A42: Total The1-Credit | D42: =SUM(D37:D41) -> 3025.83 | E42: =SUM(E35:E41) -> 1928.975 | F42: =SUM(F35:F41) -> 1096.855
E44: =SUM(E42,E34,E26,E18,E10) -> 17857.21 | F44: =SUM(F42,F34,F26,F18,F10) -> 7262.41

Sheet May22
A2: Homepro | B2: 44689 | C2: Bill Cut 18 | D2: Total | E2: G | F2: N | H2: F Amount | I2: Per Month | J2: Dif INT
A3: 44639 | B3: KASOSHOPPING.COM-KASPAKEY Renew | D3: 740 | E3: =D3 -> 740
A4: 44647 | B4: ROBINSON-BANGKAE | D4: 1090 | E4: =D4 -> 1090
A5: 44647 | B5: BAR BQ PLAZA-SEACON | D5: 1049 | E5: =D5/2 -> 524.5 | F5: =E5 -> 524.5
A6: 44669 | B6: PIZZA Company | D6: 565 | E6: =D6/2 -> 282.5 | F6: =E6 -> 282.5
A7: 44638 | B7: RENTOKIL INITIAL | C7: 004/006 | D7: 3564.88 | E7: =D7/2 -> 1782.44 | F7: =E7 -> 1782.44
A8: 44638 | B8: Shoppee Pay | C8: 003/010 | D8: 1590 | E8: 1590
A9: 44638 | B9: ODP-SEACON | C9: 002/003 | D9: 512.24 | E9: 512.24 | F9: 0 | H9: 1510 | I9: =H9/3 -> 503.33333 | J9: =D9-I9 -> 8.9066667
A10: 44638 | B10: ODP-SEACON | C10: 002/003 | D10: 736.14 | E10: =J10/2 -> 6.4033333 | F10: =D10-E10 -> 729.73667 | H10: 2170 | I10: =H10/3 -> 723.33333 | J10: =D10-I10 -> 12.806667
A11: 44638 | B11: MI-SHOP SEACON | C11: 002/003 | D11: 2035.06 | E11: =J11/2 -> 17.696667 | F11: =D11-E11 -> 2017.3633 | H11: 5999 | I11: =H11/3 -> 1999.6667 | J11: =D11-I11 -> 35.393333
A12: Total HomePro | D12: =SUM(D3:D11) -> 11882.32 | E12: =SUM(E3:E11) -> 6545.78 | F12: =SUM(F3:F11) -> 5336.54
A14: K-Credit | B14: 44684 | C14: Bill Cut 17 | D14: Total | E14: G | F14: N
A15: 44640 | B15: True Online-9605716975 | D15: 854.93 | E15: =D15 -> 854.93
A16: 44640 | B16: True Vision-139380656 | D16: 1603.93 | E16: =D16 -> 1603.93
A17: 44640 | B17: Shoppee-Sketcher | D17: 1183 | E17: =D17 -> 1183
A18: 44668 | B18: Shoppee Pay | C18: 008/010 | D18: 319 | E18: =D18 -> 319
A19: 44668 | B19: Shoppee Pay | C19: 003/010 | D19: 320 | E19: =D19 -> 320
A20: 44668 | B20: Cash Back | D20: -10.7 | E20: =D20 -> -10.7
A21: Total K-Credit | D21: =SUM(D15:D20) -> 4270.16 | E21: =SUM(E15:E20) -> 4270.16 | F21: =SUM(F15:F20) -> 0
A23: KTC-Credit | B23: 44683 | C23: Bill Cut 18 | D23: Total | E23: G | F23: N
A24: 44641 | B24: KTAXA Insurance | D24: 1191.87 | E24: =D24 -> 1191.87
E25: =D25 -> 0 | H25: =D25*6 -> 0
E26: =D26 -> 0 | H26: =D26*6 -> 0
E28: =D28 -> 0
A29: Total KTC-Credit | D29: =SUM(D24:D28) -> 1191.87 | E29: =SUM(E24:E28) -> 1191.87 | F29: =SUM(F24:F28) -> 0
A31: AEON-Big C Credit | B31: 44683 | C31: Bill Cut 10 | D31: Total | E31: G | F31: N
A32: 44633 | B32: BIG C- Bangbon | D32: 1121 | E32: =D32/2 -> 560.5 | F32: =E32 -> 560.5
B34: MINI BIG C- BCP Kanlapap
A37: Total AEON-Big C-Credit | D37: =SUM(D32:D36) -> 1121 | E37: =SUM(E32:E36) -> 560.5 | F37: =SUM(F32:F36) -> 560.5
A39: CITY BANK | B39: 44682 | C39: Bill Cut 7 | D39: Total | E39: G | F39: N
E40: =D40 -> 0
E42: =D42/2 -> 0 | F42: =E42 -> 0
E43: =D43/2 -> 0 | F43: =E43 -> 0
E44: =D44 -> 0
A45: Total CITYBANK | D45: =SUM(D40:D44) -> 0 | E45: =SUM(E40:E44) -> 0 | F45: =SUM(F40:F44) -> 0
A47: SHOPPY PAY | B47: 44682 | C47: Bill Cut 24 | D47: Total | E47: G | F47: N
A48: 44671 | B48: Intex ผ้าคลุมสระ | D48: 452 | E48: =D48 -> 452
E50: =D50/2 -> 0 | F50: =E50 -> 0
E51: =D51/2 -> 0 | F51: =E51 -> 0
E52: =D52 -> 0
...

Sheet Jun22
A2: Homepro | B2: 44719 | C2: Bill Cut 18 | D2: Total | E2: G | F2: N | H2: F Amount | I2: Per Month | J2: Dif INT | L2: K-Bank | M2: SCB | N2: BAY
A3: 44669 | B3: Steam Purchase | D3: 836.83 | E3: =D3 -> 836.83
A4: 44670 | B4: PTTST. ปั้มชิงช้า | D4: 1350 | F4: 1350
A5: 44675 | B5: Foodland | D5: 658 | E5: =D5/2 -> 329 | F5: =D5/2 -> 329
A6: 44677 | B6: ST.Louis | D6: 3549 | E6: =D6 -> 3549
A7: 44678 | B7: Vichaivej | D7: 230 | E7: =D7 -> 230
A8: 44699 | B8: RENTOKIL INITIAL | C8: 005/006 | D8: 3564.88 | E8: =D8/2 -> 1782.44 | F8: =E8 -> 1782.44
A9: 44699 | B9: Shoppee Pay | C9: 004/010 | D9: 1590 | E9: 1590 | F9: 0
A10: 44699 | B10: Garmin Venu2 Plus | C10: 001/010 | D10: =14082/10 -> 1408.2 | E10: =D10 -> 1408.2
A11: 44699 | B11: ODP-SEACON | C11: 003/003 | D11: 518.58 | E11: =D11 -> 518.58 | H11: 1510 | I11: =H11/3 -> 503.33333 | J11: =D11-I11 -> 15.246667
A12: 44699 | B12: ODP-SEACON | C12: 003/003 | D12: 745.25 | E12: =J12/2 -> 10.958333 | F12: =D12-E12 -> 734.29167 | H12: 2170 | I12: =H12/3 -> 723.33333 | J12: =D12-I12 -> 21.916667
A13: 44699 | B13: MI-SHOP SEACON | C13: 003/003 | D13: 2060.32 | E13: =J13/2 -> 30.326667 | F13: =D13-E13 -> 2029.9933 | H13: 5999 | I13: =H13/3 -> 1999.6667 | J13: =D13-I13 -> 60.653333
A14: Total HomePro | D14: =SUM(D3:D13) -> 16511.06 | E14: =SUM(E3:E13) -> 10285.335 | F14: =SUM(F3:F13) -> 6225.725 | N14: =D14 -> 16511.06
A16: K-Credit | B16: 44713 | C16: Bill Cut 17 | D16: Total | E16: G | F16: N
A17: 44671 | B17: True Online-9605716975 | D17: 854.93 | E17: =D17 -> 854.93
A18: 44671 | B18: True Vision-139380656 | D18: 1603.93 | E18: =D18 -> 1603.93
A19: 44697 | B19: True MoveH-0838806238 | D19: 86.02 | E19: =D19 -> 86.02
A20: 44698 | B20: Shoppee Pay-Mouse | C20: 009/010 | D20: 319 | E20: =D20 -> 319
A21: 44698 | B21: Shoppee Pay-Alpinestar | C21: 004/010 | D21: 320 | E21: =D21 -> 320
A22: 44698 | B22: Cash Back | D22: -7.95 | E22: =D22 -> -7.95
A23: Total K-Credit | D23: =SUM(D17:D22) -> 3175.93 | E23: =SUM(E17:E22) -> 3175.93 | F23: =SUM(F17:F22) -> 0 | L23: =D23 -> 3175.93
A25: KTC-Credit | B25: 44713 | C25: Bill Cut 18 | D25: Total | E25: G | F25: N
A26: 44671 | B26: KTAXA Insurance | D26: 1191.87 | E26: =D26 -> 1191.87
E27: =D27 -> 0 | H27: =D27*6 -> 0
E28: =D28 -> 0 | H28: =D28*6 -> 0
E30: =D30 -> 0
A31: Total KTC-Credit | D31: =SUM(D26:D30) -> 1191.87 | E31: =SUM(E26:E30) -> 1191.87 | F31: =SUM(F26:F30) -> 0
A33: AEON-Big C Credit | B33: 44713 | C33: Bill Cut 10 | D33: Total | E33: G | F33: N
A34: 44661 | B34: PTTST. | D34: 1400 | E34: =D34 -> 1400
A35: 44664 | B35: Sukishi BQ | D35: 1197 | E35: =D35/2 -> 598.5 | F35: =E35 -> 598.5
A36: 44665 | B36: BIG C- Petkasem 2 | D36: 1846 | E36: 1078 | F36: 768
A37: 44667 | B37: MINI BIG C- Bangbon 5 | D37: 443.5 | E37: 280.5 | F37: 163
A38: 44675 | B38: BIG C- Petkasem | D38: 730.25 | E38: 365.125 | F38: 365.125
A39: Total AEON-Big C-Credit | D39: =SUM(D34:D38) -> 5616.75 | E39: =SUM(E34:E38) -> 3722.125 | F39: =SUM(F34:F38) -> 1894.625 | L39: =D39 -> 5616.75
A41: CITY BANK | B41: 44713 | C41: Bill Cut 7 | D41: Total | E41: G | F41: N
A42: 44668 | B42: COM7-Ipad Pro 11 | C42: 001/024 | D42: 1390.24 | E42: =D42 -> 1390.24 | H42: 33363 | I42: =H42/24 -> 1390.125
E44: =D44/2 -> 0 | F44: =E44 -> 0
E45: =D45/2 -> 0 | F45: =E45 -> 0
E46: =D46 -> 0
A47: Total CITYBANK | D47: =SUM(D42:D46) -> 1390.24 | E47: =SUM(E42:E46) -> 1390.24 | F47: =SUM(F42:F46) -> 0
...

Sheet Jul22
A1: Update 28/06/22
A2: Homepro | B2: 44750 | C2: Bill Cut 18 | D2: Total | E2: G | F2: N | H2: F Amount | I2: Per Month | J2: Dif INT | L2: K-Bank | M2: SCB | N2: BAY
A3: 44700 | B3: The Match Run 2022 | D3: 750 | E3: 750
A4: 44700 | B4: Shoppee Pay-เสื้อกันฝนเด็ก | D4: 216 | E4: =D4 -> 216
A5: 44703 | B5: Food Land | D5: 324.25 | E5: 162.13 | F5: 162.13
A6: 44706 | B6: Line Man-สี | D6: 130 | E6: =D6 -> 130
A7: 44706 | B7: Steam Purchase | D7: 198.6 | E7: =D7 -> 198.6
A8: 44709 | B8: Lazada-Speedo | D8: 575.6 | E8: 575.6
A9: 44710 | B9: 425 Degree Case Ipad pro | D9: 990 | E9: 990
A10: 44717 | B10: Steam Purchase | D10: 198.6 | E10: =D10 -> 198.6
A11: 44723 | B11: Steam Purchase | D11: 139 | E11: =D11 -> 139
A12: 44730 | B12: RENTOKIL INITIAL | C12: 006/006 | D12: 3564.9 | E12: =D12/2 -> 1782.45 | F12: =D12/2 -> 1782.45
A13: 44730 | B13: Shoppee Pay-Anda Seat | C13: 005/010 | D13: 1590 | E13: 1590
A14: 44730 | B14: Garmin Venu2 Plus | C14: 002/010 | D14: =14082/10 -> 1408.2 | E14: =D14 -> 1408.2
A17: Total HomePro | D17: =SUM(D3:D16) -> 10085.15 | E17: =SUM(E3:E16) -> 8140.58 | F17: =SUM(F3:F16) -> 1944.58 | N17: =D17 -> 10085.15
A19: K-Credit | B19: 44746 | C19: Bill Cut 17 | D19: Total | E19: G | F19: N
A20: 44701 | B20: True Online-9605716975 | D20: 854.93 | E20: =D20 -> 854.93
A21: 44701 | B21: True Vision-139380656 | D21: 1603.93 | E21: =D21 -> 1603.93
A22: 44699 | B22: True MoveH-0838806238-จ่าย TrueWallet
A23: 44729 | B23: Shoppee Pay-Mouse | C23: 010/010 | D23: 319 | E23: =D23 -> 319
A24: 44729 | B24: Shoppee Pay-ถุงมือ | C24: 005/010 | D24: 320 | E24: =D24 -> 320
A25: 44729 | B25: Cash Back | D25: -7.74 | E25: =D25 -> -7.74
A26: Total K-Credit | D26: =SUM(D20:D25) -> 3090.12 | E26: =SUM(E20:E25) -> 3090.12 | F26: =SUM(F20:F25) -> 0 | L26: =D26 -> 3090.12
A28: KTC-Credit | B28: 44745 | C28: Bill Cut 18 | D28: Total | E28: G | F28: N
A29: 44701 | B29: KTAXA Insurance | D29: 1191.87 | E29: =D29 -> 1191.87
E30: =D30 -> 0 | H30: =D30*6 -> 0
E31: =D31 -> 0 | H31: =D31*6 -> 0
E33: =D33 -> 0
A34: Total KTC-Credit | D34: =SUM(D29:D33) -> 1191.87 | E34: =SUM(E29:E33) -> 1191.87 | F34: =SUM(F29:F33) -> 0
A36: AEON-Big C Credit | B36: 44744 | C36: Bill Cut 10 | D36: Total | E36: G | F36: N
A37: 44691 | B37: ST.Louis | D37: 1035 | E37: =D37 -> 1035
A38: 44696 | B38: SSP SPN West Gate-ชุดว่ายน้ำ | D38: 979 | E38: =D38/2 -> 489.5 | F38: =E38 -> 489.5
A39: 44696 | B39: MK - CTWG | D39: 815 | E39: =D39/2 -> 407.5 | F39: =E39 -> 407.5
A42: Total AEON-Big C-Credit | D42: =SUM(D37:D41) -> 2829 | E42: =SUM(E37:E41) -> 1932 | F42: =SUM(F37:F41) -> 897 | L42: =D42 -> 2829
A44: CITY BANK | B44: 44746 | C44: Bill Cut 7 | D44: Total | E44: G | F44: N | H44: ยอดเต็ม | I44: ผ่อน/เดือน
A45: 44719 | B45: AIS SHOP-P'TIM | C45: 015/030 | D45: 1094.03
A46: 44719 | B46: COM7-Ipad Pro 11" | C46: 002/024 | D46: 1390.12 | E46: =D46 -> 1390.12 | H46: 33363 | I46: =H46/24 -> 1390.125
A47: 44719 | B47: COM7-Magic Keyborad | C47: 001/024 | D47: =I47 -> 412.5 | E47: =D47 -> 412.5 | H47: 9900 | I47: =H47/24 -> 412.5 | J47: =412.5*24 -> 9900
A48: 44719 | B48: COM7-Apple Pencil2 | C48: 001/024 | D48: =I48-3.67 -> 183.41333 | E48: =D48 -> 183.41333 | H48: 4490 | I48: =H48/24 -> 187.08333 | J48: =187.08*24 -> 4489.92
A49: 44719 | B49: COM7-Iphone 13-P'TIM | C49: 001/024 | D49: 1378.75 | H49: 33090 | I49: =H49/24 -> 1378.75 | J49: =1378.75*24 -> 33090
...

Sheet Aug22
A2: Homepro | B2: 44780 | C2: Bill Cut 18 | D2: Total | E2: G | F2: N | H2: F Amount | I2: Per Month | J2: Dif INT | L2: K-Bank | M2: SCB | N2: BAY
A3: 44760 | B3: Shoppee Pay-Anda Seat | C3: 006/010 | D3: 1590 | E3: 1590
A4: 44760 | B4: Garmin Venu2 Plus | C4: 003/010 | D4: =14082/10 -> 1408.2 | E4: =D4 -> 1408.2
A5: 44760 | B5: D Four Carcity | C5: 001/003 | D5: 1964.36 | E5: =1964.36/2 -> 982.18 | F5: =E5 -> 982.18 | H5: 5784.8 | I5: =H5/3 -> 1928.2667
A6: 44730 | B6: Steam Purchase | D6: 69.3 | E6: =D6 -> 69.3
A7: 44738 | B7: Santa Fe Steak | D7: 446 | E7: =D7/2 -> 223 | F7: =D7/2 -> 223
A8: 44748 | B8: Steam Purchase | D8: 357 | E8: =D8 -> 357
A9: 44755 | B9: BOOT-Seacon bangkae | D9: 317 | E9: 179 | F9: =D9-E9 -> 138
A12: Total HomePro | D12: =SUM(D3:D11) -> 6151.86 | E12: =SUM(E3:E11) -> 4808.68 | F12: =SUM(F3:F11) -> 1343.18 | N12: =D12 -> 6151.86
A14: K-Credit | B14: 44774 | C14: Bill Cut 17 | D14: Total | E14: G | F14: N
A15: 44732 | B15: True Online-9605716975 | D15: 854.93 | E15: =D15 -> 854.93
A16: 44732 | B16: True Vision-139380656 | D16: 1603.93 | E16: =D16 -> 1603.93
A17: 44730 | B17: True MoveH-0838806238 | D17: 373.43 | E17: =D17 -> 373.43
A18: 44759 | B18: Shoppee Pay | C18: 006/010 | D18: 320 | E18: =D18 -> 320
A19: 44759 | B19: Cash Back | D19: -7.88 | E19: =D19 -> -7.88
A21: Total K-Credit | D21: =SUM(D15:D20) -> 3144.41 | E21: =SUM(E15:E20) -> 3144.41 | F21: =SUM(F15:F20) -> 0 | L21: =D21 -> 3144.41
A23: KTC-Credit | B23: =B14 -> 44774 | C23: Bill Cut 18 | D23: Total | E23: G | F23: N
A24: 44733 | B24: KTAXA Insurance | D24: 1191.87 | E24: =D24 -> 1191.87
E25: =D25 -> 0 | H25: =D25*6 -> 0
E26: =D26 -> 0 | H26: =D26*6 -> 0
E28: =D28 -> 0
A29: Total KTC-Credit | D29: =SUM(D24:D28) -> 1191.87 | E29: =SUM(E24:E28) -> 1191.87 | F29: =SUM(F24:F28) -> 0 | O29: KTB
A31: AEON-Big C Credit | B31: =B23 -> 44774 | C31: Bill Cut 10 | D31: Total | E31: G | F31: N
A32: 44724 | B32: BIG C- Petkasem 2 | D32: 1035.75 | E32: =D32-F32 -> 740.125 | F32: =778.5-F33-F34 -> 295.625
A33: 44731 | B33: MINI BIG C | D33: 381 | E33: =D33/2 -> 190.5 | F33: =E33 -> 190.5
A34: 44748 | B34: BIG C- Petkasem 2 | D34: 584.75 | E34: =D34/2 -> 292.375 | F34: =E34 -> 292.375
A35: 44733 | B35: MAJOR CINEPLEX | D35: 539 | E35: 539
A37: Total AEON-Big C-Credit | D37: =SUM(D32:D36) -> 2540.5 | E37: =SUM(E32:E36) -> 1762 | F37: =SUM(F32:F36) -> 778.5 | L37: =D37 -> 2540.5
A39: CITY BANK | B39: =B31 -> 44774 | C39: Bill Cut 7 | D39: Total | E39: G | F39: N | H39: ยอดเต็ม | I39: ผ่อน/เดือน
A40: 44749 | B40: AIS SHOP-P'TIM | C40: 016/030 | D40: 1094.03
A41: 44749 | B41: COM7-Ipad Pro 11" | C41: 003/024 | D41: 1390.12 | E41: =D41 -> 1390.12 | H41: 33363 | I41: =H41/24 -> 1390.125
A42: 44749 | B42: COM7-Magic Keyborad | C42: 002/024 | D42: =I42 -> 416.25 | E42: =D42 -> 416.25 | H42: 9990 | I42: =H42/24 -> 416.25
A43: 44749 | B43: COM7-Apple Pencil2 | C43: =C42 -> 002/024 | D43: =I43-3.75 -> 183.33333 | E43: =D43 -> 183.33333 | H43: 4490 | I43: =H43/24 -> 187.08333
A44: 44749 | B44: COM7-Iphone 13-P'TIM | C44: =C43 -> 002/024 | D44: 1378.75 | H44: 33090 | I44: =H44/24 -> 1378.75
B45: Cash Back
A47: Total CITYBANK | D47: =SUM(D40:D46) -> 4462.4833 | E47: =SUM(E40:E46) -> 1989.7033 | F47: =SUM(F40:F46) -> 0 | O47: KTB
A49: Spaylater | B49: =B39 -> 44774 | D49: Total | E49: G | F49: N
A50: 44707 | B50: Skechers Good Year Gorun | C50: 002/002 | D50: 562.63 | E50: =D50 -> 562.63
A51: 44752 | B51: GMM USB | D51: 269 | E51: =D51 -> 269
A52: 44763 | B52: Domino | D52: 60 | E52: 60
...

Sheet Sep22
A2: Homepro | B2: 44811 | C2: Bill Cut 18 | D2: Total | E2: G | F2: N | H2: F Amount | I2: Per Month | J2: Dif INT | L2: K-Bank | M2: SCB | N2: BAY
A3: 44791 | B3: Shoppee Pay-Anda Seat | C3: 007/010 | D3: 1590 | E3: 1590
A4: 44791 | B4: Garmin Venu2 Plus | C4: 004/010 | D4: =14082/10 -> 1408.2 | E4: =D4 -> 1408.2
A5: 44791 | B5: D Four Carcity | C5: 002/003 | D5: 1964.36 | E5: =1964.36/2 -> 982.18 | F5: =E5 -> 982.18
A6: 44761 | B6: Steam Purchase | D6: 198.6 | E6: 198.6
A7: 44763 | B7: Steam Purchase | D7: 317.05 | E7: 317.05
A8: 44765 | B8: PTT-MAHACHAI | D8: 1390 | E8: 1390
A9: 44766 | B9: BBQ -Plaza | D9: 804 | E9: =D9/2 -> 402 | F9: =E9 -> 402
A10: 44773 | B10: Vichaivej | D10: 1448 | E10: =D10/2 -> 724 | F10: =E10 -> 724
A11: Total HomePro | D11: =SUM(D3:D10) -> 9120.21 | E11: =SUM(E3:E10) -> 7012.03 | F11: =SUM(F3:F10) -> 2108.18 | N11: =D11 -> 9120.21
A13: K-Credit | B13: 44805 | C13: Bill Cut 17 | D13: Total | E13: G | F13: N
A14: 44762 | B14: True Online-9605716975 | D14: 854.93 | E14: =D14 -> 854.93
A15: 44762 | B15: True Vision-139380656 | D15: 1603.93 | E15: =D15 -> 1603.93
A16: 44760 | B16: True MoveH-0838806238 | D16: 373.43 | E16: =D16 -> 373.43
A17: 44790 | B17: Shoppee Pay | C17: 007/010 | D17: 320 | E17: =D17 -> 320
A18: 44790 | B18: Cash Back | D18: -7.88 | E18: =D18 -> -7.88
A20: Total K-Credit | D20: =SUM(D14:D19) -> 3144.41 | E20: =SUM(E14:E19) -> 3144.41 | F20: =SUM(F14:F19) -> 0 | L20: =D20 -> 3144.41
A22: KTC-Credit | B22: =B13 -> 44805 | C22: Bill Cut 18 | D22: Total | E22: G | F22: N
A23: 44762 | B23: KTAXA Insurance | D23: 1191.87 | E23: =D23 -> 1191.87
A28: Total KTC-Credit | D28: =SUM(D23:D27) -> 1191.87 | E28: =SUM(E23:E27) -> 1191.87 | F28: =SUM(F23:F27) -> 0
A30: AEON-Big C Credit | B30: =B22 -> 44805 | C30: Bill Cut 10 | D30: Total | E30: G | F30: N
A31: 44755 | B31: DOOKKI KOREAN | D31: 598 | E31: =D31/2 -> 299 | F31: =E31 -> 299
A32: 44759 | B32: BIG-C Petkaseam | D32: 336.5 | E32: =D32/2 -> 168.25 | F32: =E32 -> 168.25
A33: 44766 | B33: BIG-C Petkaseam 2 | D33: 911.75 | E33: =D33-F33 -> 415.75 | F33: 496
A34: 44780 | B34: BIG-C Petkaseam 2 | D34: 757.5 | E34: =D34-F34 -> 329.5 | F34: 428
A36: Total AEON-Big C-Credit | D36: =SUM(D31:D35) -> 2603.75 | E36: =SUM(E31:E35) -> 1212.5 | F36: =SUM(F31:F35) -> 1391.25 | L36: =D36 -> 2603.75
A38: CITY BANK | B38: =B30 -> 44805 | C38: Bill Cut 7 | D38: Total | E38: G | F38: N | H38: ยอดเต็ม | I38: ผ่อน/เดือน
A39: 44780 | B39: AIS SHOP-P'TIM | C39: 017/030 | D39: 1094.03
A40: =A39 -> 44780 | B40: COM7-Ipad Pro 11" | C40: 004/024 | D40: 1390.12 | E40: =D40 -> 1390.12 | H40: 33363 | I40: =H40/24 -> 1390.125
A41: =A40 -> 44780 | B41: COM7-Magic Keyborad | C41: 003/024 | D41: =I41 -> 416.25 | E41: =D41 -> 416.25 | H41: 9990 | I41: =H41/24 -> 416.25
A42: =A41 -> 44780 | B42: COM7-Apple Pencil2 | C42: =C41 -> 003/024 | D42: =I42-3.75 -> 183.33333 | E42: =D42 -> 183.33333 | H42: 4490 | I42: =H42/24 -> 187.08333
A43: =A42 -> 44780 | B43: COM7-Iphone 13-P'TIM | C43: =C42 -> 003/024 | D43: 1378.75 | H43: 33090 | I43: =H43/24 -> 1378.75
B44: Cash Back
A46: Total CITYBANK | D46: =SUM(D39:D45) -> 4462.4833 | E46: =SUM(E39:E45) -> 1989.7033 | F46: =SUM(F39:F45) -> 0
A48: Spaylater | B48: =B38 -> 44805 | D48: Total | E48: G | F48: N
A49: 44798 | B49: Masterkool Fan | C49: 001/006 | D49: 214.67 | E49: 214.67
A50: 44781 | B50: Mototech BlueTooth | D50: 228 | E50: =D50 -> 228
A54: Total Spaylater | D54: =SUM(D49:D53) -> 442.67 | E54: =SUM(E49:E53) -> 442.67 | F54: =SUM(F49:F53) -> 0
A56: The1-Credit | B56: 44826 | C56: Bill Cut 2 | D56: Total | E56: G | F56: N
A57: 44776 | B57: NetFLIX หัก Ipad | D57: 419 | E57: =D57 -> 419
...

Sheet Oct22
A2: Homepro | B2: 44842 | C2: Bill Cut 18 | D2: Total | E2: G | F2: N | H2: F Amount | I2: Per Month | J2: Dif INT | L2: K-Bank | M2: SCB | N2: BAY | O2: KTB
A3: 44822 | B3: Shoppee Pay-Anda Seat | C3: 008/010 | D3: 1590 | E3: 1590
A4: 44822 | B4: Garmin Venu2 Plus | C4: 005/010 | D4: =14082/10 -> 1408.2 | E4: =D4 -> 1408.2
A5: 44822 | B5: D Four Carcity | C5: 003/003 | D5: 1954.25 | E5: 977.13 | F5: 977.12
A6: 44794 | B6: Sukishi BQ | D6: 1087 | E6: =D6/2 -> 543.5 | F6: =E6 -> 543.5
A7: 44794 | B7: Orental Princess | D7: 1004.25 | E7: 405 | F7: =D7-E7 -> 599.25
A8: 44796 | B8: Steam Purchase | D8: =107.1+198.6 -> 305.7 | E8: =D8 -> 305.7
A9: 44803 | B9: Steam Purchase | D9: 219 | E9: =D9 -> 219
A10: 44808 | B10: You and I | D10: 1547.22 | E10: =D10/2 -> 773.61 | F10: =E10 -> 773.61
A11: Total HomePro | D11: =SUM(D3:D10) -> 9115.62 | E11: =SUM(E3:E10) -> 6222.14 | F11: =SUM(F3:F10) -> 2893.48 | N11: =D11 -> 9115.62
A13: K-Credit | B13: 44837 | C13: Bill Cut 17 | D13: Total | E13: G | F13: N
A14: 44807 | B14: 7-11 Online Saiya | D14: 500 | E14: =D14 -> 500
A15: 44808 | B15: Haborland | D15: 1999
A17: 44821 | B17: Shoppee Pay | C17: 008/010 | D17: 320 | E17: =D17 -> 320
A18: =A17 -> 44821 | B18: Cash Back | D18: -10.79 | E18: =D18 -> -10.79
A20: Total K-Credit | D20: =SUM(D14:D19) -> 2808.21 | E20: =SUM(E14:E19) -> 809.21 | F20: =SUM(F14:F19) -> 0 | L20: =D20-1999 -> 809.21
A22: KTC-Credit | B22: =B13 -> 44837 | C22: Bill Cut 18 | D22: Total | E22: G | F22: N
A23: 44795 | B23: KTAXA Insurance | D23: 1191.87 | E23: =D23 -> 1191.87
A28: Total KTC-Credit | D28: =SUM(D23:D27) -> 1191.87 | E28: =SUM(E23:E27) -> 1191.87 | F28: =SUM(F23:F27) -> 0 | O28: =D28 -> 1191.87
A30: AEON-Big C Credit | B30: 44836 | C30: Bill Cut 10 | D30: Total | E30: G | F30: N
A31: 44785 | B31: BIG-C Petkaseam | D31: 1440.25 | E31: =D31/2 -> 720.125 | F31: =E31 -> 720.125
A32: 44793 | B32: Mini Big C | D32: 332.5 | E32: =D32/2 -> 166.25 | F32: =E32 -> 166.25
A36: Total AEON-Big C-Credit | D36: =SUM(D31:D35) -> 1772.75 | E36: =SUM(E31:E35) -> 886.375 | F36: =SUM(F31:F35) -> 886.375 | L36: =D36 -> 1772.75
A38: CITY BANK | B38: 44837 | C38: Bill Cut 7 | D38: Total | E38: G | F38: N | H38: ยอดเต็ม | I38: ผ่อน/เดือน
A39: 44811 | B39: AIS SHOP-P'TIM | C39: 018/030 | D39: 1094.03
A40: =A39 -> 44811 | B40: COM7-Ipad Pro 11" | C40: 005/024 | D40: 1390.12 | E40: =D40 -> 1390.12 | H40: 33363 | I40: =H40/24 -> 1390.125
A41: =A40 -> 44811 | B41: COM7-Magic Keyborad | C41: 004/024 | D41: =I41 -> 416.25 | E41: =D41 -> 416.25 | H41: 9990 | I41: =H41/24 -> 416.25
A42: =A41 -> 44811 | B42: COM7-Apple Pencil2 | C42: =C41 -> 004/024 | D42: =I42-3.75 -> 183.33333 | E42: =D42 -> 183.33333 | H42: 4490 | I42: =H42/24 -> 187.08333
A43: =A42 -> 44811 | B43: COM7-Iphone 13-P'TIM | C43: =C42 -> 004/024 | D43: 1378.75 | H43: 33090 | I43: =H43/24 -> 1378.75
B44: Cash Back | D44: -474.8 | E44: =D44 -> -474.8
A46: Total CITYBANK | D46: =SUM(D39:D45) -> 3987.6833 | E46: =SUM(E39:E45) -> 1514.9033 | F46: =SUM(F39:F45) -> 0 | O46: =E46 -> 1514.9033
A48: Spaylater | B48: =B38 -> 44837 | D48: Total | E48: G | F48: N
A49: 44829 | B49: Masterkool Fan | C49: 002/006 | D49: 214.67 | E49: 214.67
A50: 44817 | B50: Trinity Seven | D50: 144 | E50: =D50 -> 144
A54: Total Spaylater | D54: =SUM(D49:D53) -> 358.67 | E54: =SUM(E49:E53) -> 358.67 | F54: =SUM(F49:F53) -> 0 | O54: =E54 -> 358.67
A56: Play next | B56: =B46 -> 0 | D56: Total | E56: G | F56: N
B57: True Online-9605716975 | D57: 854.93 | E57: =D57 -> 854.93
B58: True Vision-139380656 | D58: 1603.93 | E58: =D58 -> 1603.93
B59: True MoveH-0838806238 | D59: 373.43 | E59: =D59 -> 373.43
A62: Total Spaylater | D62: =SUM(D57:D61) -> 2832.29 | E62: =SUM(E57:E61) -> 2832.29 | F62: =SUM(F57:F61) -> 0 | O62: =E62 -> 2832.29
...

Sheet Nov22
A2: Homepro | B2: 44872 | C2: Bill Cut 18 | D2: Total | E2: G | F2: N | G2: REC | H2: F Amount | I2: Per Month | J2: Dif INT | L2: K-Bank | M2: SCB | N2: BAY | O2: KTB
A3: 44852 | B3: Shoppee Pay-Anda Seat | C3: 009/010 | D3: 1590 | E3: 1590
A4: =A3 -> 44852 | B4: Garmin Venu2 Plus | C4: 006/010 | D4: =14082/10 -> 1408.2 | E4: =D4 -> 1408.2
A5: 44829 | B5: MengNur | D5: 580 | E5: 290 | F5: 290
A6: 44833 | B6: Steam Purchase | D6: 198.6 | E6: =D6 -> 198.6
A11: Total HomePro | D11: =SUM(D3:D10) -> 3776.8 | E11: =SUM(E3:E10) -> 3486.8 | F11: =SUM(F3:F10) -> 290 | N11: =D11 -> 3776.8
A13: K-Credit | B13: 44866 | C13: Bill Cut 17 | D13: Total | E13: G | F13: N | G13: REC
A14: 44824 | B14: True Online-9605716975 | D14: 854.93 | E14: =D14 -> 854.93
A15: =A14 -> 44824 | B15: True Vision-139380656 | D15: 1603.93 | E15: =D15 -> 1603.93
A16: 44822 | B16: True MoveH-0838806238 | D16: 373.43 | E16: =D16 -> 373.43
A17: 44851 | B17: Shoppee Pay | C17: 009/010 | D17: 320 | E17: =D17 -> 320
A18: =A17 -> 44851 | B18: Cash Back | D18: -7.88 | E18: =D18 -> -7.88
A20: Total K-Credit | D20: =SUM(D14:D19) -> 3144.41 | E20: =SUM(E14:E19) -> 3144.41 | F20: =SUM(F14:F19) -> 0 | L20: =D20 -> 3144.41
A22: KTC-Credit | B22: =B13 -> 44866 | C22: Bill Cut 18 | D22: Total | E22: G | F22: N | G22: REC
A23: 44824 | B23: KTAXA Insurance | D23: 1191.87 | E23: =D23 -> 1191.87
A24: 44839 | B24: KT-AXA PG Odinary | C24: 001/010 | D24: 2760.7 | E24: =D24 -> 2760.7
A25: 44839 | B25: KT-AXA PG INT00.74% | D25: 204.3 | E25: =D25 -> 204.3
A28: Total KTC-Credit | D28: =SUM(D23:D27) -> 4156.87 | E28: =SUM(E23:E27) -> 4156.87 | F28: =SUM(F23:F27) -> 0 | O28: =D28 -> 4156.87
A30: AEON-Big C Credit | B30: =B22 -> 44866 | C30: Bill Cut 10 | D30: Total | E30: G | F30: N | G30: REC
A31: 44822 | B31: BIG-C Petkaseam 2 | D31: 1664.5 | E31: =D31/2 -> 832.25 | F31: =E31 -> 832.25
A36: Total AEON-Big C-Credit | D36: =SUM(D31:D35) -> 1664.5 | E36: =SUM(E31:E35) -> 832.25 | F36: =SUM(F31:F35) -> 832.25 | L36: =D36 -> 1664.5
A38: CITY BANK | B38: 44868 | C38: Bill Cut 7 | D38: Total | E38: G | F38: N | G38: REC | H38: ยอดเต็ม | I38: ผ่อน/เดือน | J38: คงเหลือ
A39: 44841 | B39: AIS SHOP-P'TIM | C39: 019/030 | D39: 1094.03
A40: =A39 -> 44841 | B40: COM7-Ipad Pro 11" | C40: 006/024 | D40: 1390.12 | E40: =D40 -> 1390.12 | H40: 33363 | I40: =H40/24 -> 1390.125 | J40: =H40-(I40*6) -> 25022.25
A41: =A40 -> 44841 | B41: COM7-Magic Keyborad | C41: 005/024 | D41: =I41 -> 416.25 | E41: =D41 -> 416.25 | H41: 9990 | I41: =H41/24 -> 416.25 | J41: =H41-(I41*5) -> 7908.75
A42: =A41 -> 44841 | B42: COM7-Apple Pencil2 | C42: =C41 -> 005/024 | D42: =I42-3.75 -> 183.33333 | E42: =D42 -> 183.33333 | H42: 4490 | I42: =H42/24 -> 187.08333 | J42: =H42-(I42*5) -> 3554.5833
A43: =A42 -> 44841 | B43: COM7-Iphone 13-P'TIM | C43: =C42 -> 005/024 | D43: 1378.75 | H43: 33090 | I43: =H43/24 -> 1378.75
B44: Cash Back
A46: Total CITYBANK | D46: =SUM(D39:D45) -> 4462.4833 | E46: =SUM(E39:E45) -> 1989.7033 | F46: =SUM(F39:F45) -> 0 | O46: =E46 -> 1989.7033
A48: Spaylater | B48: =B38 -> 44868 | D48: Total | E48: G | F48: N | G48: REC
A49: 44859 | B49: Masterkool Fan | C49: 003/006 | D49: 214.67 | E49: 214.67
A50: 44846 | B50: Yes's Delight | D50: 248 | E50: =D50 -> 248
A51: 44840 | B51: Hello Kitty เสื้อกันฝนเด็ก | D51: 201 | E51: =D51 -> 201
A52: 44832 | B52: เสื้อกันฝนผู้ใหญ่ | D52: 197 | E52: =D52 -> 197
A54: Total Spaylater | D54: =SUM(D49:D53) -> 860.67 | E54: =SUM(E49:E53) -> 860.67 | F54: =SUM(F49:F53) -> 0 | O54: =E54 -> 860.67
A56: Play next | B56: 44866 | D56: Total | E56: G | F56: N
A62: Total Spaylater | D62: =SUM(D57:D61) -> 0 | E62: =SUM(E57:E61) -> 0 | F62: =SUM(F57:F61) -> 0 | O62: =E62 -> 0
A64: The1-Credit | B64: 44887 | C64: Bill Cut 2 | D64: Total | E64: G | F64: N | G64: REC
A65: 44837 | B65: NetFLIX หัก Ipad | D65: 419 | E65: =D65 -> 419
A66: 44836 | B66: HARBOR LAND | D66: 670 | E66: 335 | F66: 335
...

Sheet Dec22
A2: Homepro | B2: 44903 | C2: Bill Cut 18 | D2: Total | E2: G | F2: N | H2: F Amount | I2: Per Month | J2: Dif INT | L2: K-Bank | M2: SCB | N2: BAY | O2: KTB
A3: 44883 | B3: Shoppee Pay-Anda Seat | C3: 010/010 | D3: 1590 | E3: 1590
A4: =A3 -> 44883 | B4: Garmin Venu2 Plus | C4: 007/010 | D4: =14082/10 -> 1408.2 | E4: =D4 -> 1408.2
A5: 44857 | B5: MK -WestG | D5: 836 | E5: =D5/2 -> 418 | F5: =E5 -> 418
A6: 44871 | B6: Steam Purchase | D6: 198.6 | E6: =D6 -> 198.6
A11: Total HomePro | D11: =SUM(D3:D10) -> 4032.8 | E11: =SUM(E3:E10) -> 3614.8 | F11: =SUM(F3:F10) -> 418 | N11: =D11 -> 4032.8
A13: K-Credit | B13: 44897 | C13: Bill Cut 17 | D13: Total | E13: G | F13: N
A14: 44854 | B14: True Online-9605716975 | D14: 854.93 | E14: =D14 -> 854.93
A15: =A14 -> 44854 | B15: True Vision-139380656 | D15: 1603.93 | E15: =D15 -> 1603.93
A16: 44852 | B16: True MoveH-0838806238 | D16: 373.43 | E16: =D16 -> 373.43
A17: 44882 | B17: Shoppee Pay | C17: 010/010 | D17: 320 | E17: =D17 -> 320
A18: =A17 -> 44882 | B18: Cash Back | D18: -7.88 | E18: =D18 -> -7.88
A20: Total K-Credit | D20: =SUM(D14:D19) -> 3144.41 | E20: =SUM(E14:E19) -> 3144.41 | F20: =SUM(F14:F19) -> 0 | L20: =D20 -> 3144.41
A22: KTC-Credit | B22: 44898 | C22: Bill Cut 18 | D22: Total | E22: G | F22: N
A23: 44854 | B23: KTAXA Insurance | D23: 1191.87 | E23: =D23 -> 1191.87
A24: 44870 | B24: KT-AXA PG Odinary | C24: 002/010 | D24: 2760.7 | E24: =D24 -> 2760.7
A25: 44870 | B25: KT-AXA PG INT00.74% | D25: 204.29 | E25: =D25 -> 204.29
A28: Total KTC-Credit | D28: =SUM(D23:D27) -> 4156.86 | E28: =SUM(E23:E27) -> 4156.86 | F28: =SUM(F23:F27) -> 0 | O28: =D28 -> 4156.86
A30: AEON-Big C Credit | B30: 44897 | C30: Bill Cut 10 | D30: Total | E30: G | F30: N
A31: 44847 | B31: Mini Big C | D31: 490.75 | E31: =D31/2 -> 245.375 | F31: =E31 -> 245.375
A32: 44847 | B32: PTTST.D | D32: 1200 | E32: =D32 -> 1200
A33: 44864 | B33: BIG-C Petkasem2 | D33: 1941.25 | E33: =D33/2 -> 970.625 | F33: =E33 -> 970.625
A34: 44865 | B34: ANNual Fee | D34: 214 | E34: =D34 -> 214
A36: Total AEON-Big C-Credit | D36: =SUM(D31:D35) -> 3846 | E36: =SUM(E31:E35) -> 2630 | F36: =SUM(F31:F35) -> 1216 | L36: =D36 -> 3846
A38: CITY BANK | B38: 44896 | C38: Bill Cut 7 | D38: Total | E38: G | F38: N | H38: ยอดเต็ม | I38: ผ่อน/เดือน
A39: 44872 | B39: AIS SHOP-P'TIM | C39: 020/030 | D39: 1094.03
A40: =A39 -> 44872 | B40: COM7-Ipad Pro 11" | C40: 007/024 | D40: 1390.12 | E40: =D40 -> 1390.12 | H40: 33363 | I40: =H40/24 -> 1390.125
A41: =A40 -> 44872 | B41: COM7-Magic Keyborad | C41: 006/024 | D41: =I41 -> 412.5 | E41: =D41 -> 412.5 | H41: 9900 | I41: =H41/24 -> 412.5
A42: =A41 -> 44872 | B42: COM7-Apple Pencil2 | C42: =C41 -> 006/024 | D42: =I42-3.75 -> 183.33333 | E42: =D42 -> 183.33333 | H42: 4490 | I42: =H42/24 -> 187.08333
A43: =A42 -> 44872 | B43: COM7-Iphone 13-P'TIM | C43: =C42 -> 006/024 | D43: 1378.75 | H43: 33090 | I43: =H43/24 -> 1378.75
B44: Cash Back
A46: Total CITYBANK | D46: =SUM(D39:D45) -> 4458.7333 | E46: =SUM(E39:E45) -> 1985.9533 | F46: =SUM(F39:F45) -> 0 | O46: =E46 -> 1985.9533
A48: Spaylater | B48: =B38 -> 44896 | D48: Total | E48: G | F48: N
A49: 44890 | B49: Masterkool Fan | C49: 004/006 | D49: 214.67 | E49: 214.67
A50: 44890 | B50: Jabra Elite 7 Active | C50: 001/006 | D50: 619.33 | E50: 619.33
A54: Total Spaylater | D54: =SUM(D49:D53) -> 834 | E54: =SUM(E49:E53) -> 834 | F54: =SUM(F49:F53) -> 0 | O54: =E54 -> 834
A56: Play next | B56: 44896 | C56: Bill Cut 15 | D56: Total | E56: G | F56: N
A57: 44852 | B57: Google Asia Pasific | D57: 200 | E57: 200
A58: 44861 | B58: 7-11 | D58: 229 | E58: =D58 -> 229
A62: Total Spaylater | D62: =SUM(D57:D61) -> 429 | E62: =SUM(E57:E61) -> 429 | F62: =SUM(F57:F61) -> 0 | O62: =E62 -> 429
...

Sheet Jan23
A2: Homepro | B2: 44934 | C2: Bill Cut 18 | D2: Total | E2: G | F2: N | H2: F Amount | I2: Per Month | J2: Dif INT | L2: K-Bank | M2: SCB | N2: BAY | O2: KTB
A3: 44913 | B3: Garmin Venu2 Plus | C3: 008/010 | D3: =14082/10 -> 1408.2 | E3: =D3 -> 1408.2
A11: Total HomePro | D11: =SUM(D3:D10) -> 1408.2 | E11: =SUM(E3:E10) -> 1408.2 | F11: =SUM(F3:F10) -> 0 | N11: =D11 -> 1408.2
A13: K-Credit | B13: 44928 | C13: Bill Cut 17 | D13: Total | E13: G | F13: N
A14: 44885 | B14: True Online-9605716975 | D14: 854.93 | E14: =D14 -> 854.93
A15: 44885 | B15: True Vision-139380656 | D15: 1603.93 | E15: =D15 -> 1603.93
A16: 44883 | B16: True MoveH-0838806238 | D16: 373.43 | E16: =D16 -> 373.43
A18: =A16 -> 44883 | B18: Cash Back | E18: =D18 -> 0
A20: Total K-Credit | D20: =SUM(D14:D19) -> 2832.29 | E20: =SUM(E14:E19) -> 2832.29 | F20: =SUM(F14:F19) -> 0 | L20: =D20 -> 2832.29
A22: KTC-Credit | B22: 44929 | C22: Bill Cut 18 | D22: Total | E22: G | F22: N
A23: 44885 | B23: KTAXA Insurance | D23: 1191.87 | E23: =D23 -> 1191.87
A24: 44900 | B24: KT-AXA PG Odinary | C24: 003/010 | D24: 2760.7 | E24: =D24 -> 2760.7
A25: =A24 -> 44900 | B25: KT-AXA PG INT00.74% | D25: 204.29 | E25: =D25 -> 204.29
A28: Total KTC-Credit | D28: =SUM(D23:D27) -> 4156.86 | E28: =SUM(E23:E27) -> 4156.86 | F28: =SUM(F23:F27) -> 0 | O28: =D28 -> 4156.86
A30: AEON-Big C Credit | B30: =B13 -> 44928 | C30: Bill Cut 10 | D30: Total | E30: G | F30: N
A31: 44847
A36: Total AEON-Big C-Credit | D36: =SUM(D31:D35) -> 0 | E36: =SUM(E31:E35) -> 0 | F36: =SUM(F31:F35) -> 0 | L36: =D36 -> 0
A38: CITY BANK | B38: =B30 -> 44928 | C38: Bill Cut 7 | D38: Total | E38: G | F38: N | H38: ยอดเต็ม | I38: ผ่อน/เดือน
A39: 44902 | B39: AIS SHOP-P'TIM | C39: 021/030 | D39: 1094.03
A40: =A39 -> 44902 | B40: COM7-Ipad Pro 11" | C40: 008/024 | D40: 1390.12 | E40: =D40 -> 1390.12 | H40: 33363 | I40: =H40/24 -> 1390.125
A41: =A40 -> 44902 | B41: COM7-Magic Keyborad | C41: 007/024 | D41: =I41 -> 416.25 | E41: =D41 -> 416.25 | H41: 9990 | I41: =H41/24 -> 416.25
A42: =A41 -> 44902 | B42: COM7-Apple Pencil2 | C42: =C41 -> 007/024 | D42: =I42-3.75 -> 183.33333 | E42: =D42 -> 183.33333 | H42: 4490 | I42: =H42/24 -> 187.08333
A43: =A42 -> 44902 | B43: COM7-Iphone 13-P'TIM | C43: =C42 -> 007/024 | D43: 1378.75 | H43: 33090 | I43: =H43/24 -> 1378.75
B44: Cash Back
A46: Total CITYBANK | D46: =SUM(D39:D45) -> 4462.4833 | E46: =SUM(E39:E45) -> 1989.7033 | F46: =SUM(F39:F45) -> 0 | O46: =E46 -> 1989.7033
A48: Spaylater | B48: =B38 -> 44928 | D48: Total | E48: G | F48: N
A49: 44920 | B49: Masterkool Fan | C49: 005/006 | D49: 214.67 | E49: 214.67
A50: =A49 -> 44920 | B50: Jabra Elite 7 Active | C50: 002/006 | D50: 619.33 | E50: 619.33
A54: Total Spaylater | D54: =SUM(D49:D53) -> 834 | E54: =SUM(E49:E53) -> 834 | F54: =SUM(F49:F53) -> 0 | O54: =E54 -> 834
A56: Play next | B56: =B48 -> 44928 | D56: Total | E56: G | F56: N
A57: 44883 | B57: Google Asia Pasific | D57: 200 | E57: 200
A62: Total Spaylater | D62: =SUM(D57:D61) -> 200 | E62: =SUM(E57:E61) -> 200 | F62: =SUM(F57:F61) -> 0 | O62: =E62 -> 200
A64: The1-Credit | B64: 44948 | C64: Bill Cut 2 | D64: Total | E64: G | F64: N
A65: 44868 | B65: NetFLIX หัก Ipad | D65: 419 | E65: =D65 -> 419
A72: Total The1-Credit | D72: =SUM(D65:D71) -> 419 | E72: =SUM(E65:E71) -> 419 | F72: =SUM(F65:F71) -> 0 | N72: =D72 -> 419
E74: =SUM(E72,E36,E28,E20,E11,E46,E54,E62) -> 11840.053 | F74: =SUM(F72,F36,F28,F20,F11,F46,F54,F62) -> 0
A75: NINK | B75: 44795 | C75: Bill Cut 2 | D75: Total | E75: G | F75: N
A76: 44774 | B76: Samsung G5 Monitor | C76: 005/010 | D76: 9000 | E76: =D76/10 -> 900
A79: Total NINK | D79: =SUM(D76:D78) -> 9000 | E79: =SUM(E76:E78) -> 900 | F79: =SUM(F76:F78) -> 0 | O79: =E79 -> 900
L81: =SUM(L2:L80) -> 2832.29 | M81: =SUM(M2:M80) -> 0 | N81: =SUM(N2:N80) -> 1827.2 | O81: =SUM(O3:O80) -> 8080.5633
...

Sheet MyExpense
A1: Date | B1: Credit Card | C1: App Payment | D1: Detail | E1: Inst.Period | F1: Due Date | G1: Payment_Code | H1: Total AMT | I1: PK_AMT | J1: NC_AMT
A2: 44618 | B2: Aeon Big C Platinum Visa | C2: K PLUS | D2: BIG C-PETCHKASEM | E2: 000/000 | F2: 44653 | G2: S | H2: 3452 | I2: 2374 | J2: 1078
A3: 44602 | B3: Aeon Big C Platinum Visa | C3: K PLUS | D3: MINI BIG C | E3: 000/000 | F3: 44653 | G3: S | H3: 148 | I3: 74 | J3: 74
A4: 44633 | B4: Aeon Big C Platinum Visa | C4: K PLUS | D4: BIG C-BANGBON | E4: 000/000 | F4: 44683 | G4: S | H4: 1121 | I4: =IF(My_Payment[[#This Row],[Payment_Code]]="S",My_Payment[[#This Row],[Total AMT]]/2,IF(My_Payment[[#This Row],[Payment_Code]]="P",My_Payment[[#This Row],[Total AMT]],0)) -> 560.5 | J4: =IF(My_Payment[[#This Row],[Payment_Code]]="S",My_Payment[[#This Row],[Total AMT]]/2,IF(My_Payment[[#This Row],[Payment_Code]]="N",My_Payment[[#This Row],[Total AMT]],0)) -> 560.5
A5: 44661 | B5: Aeon Big C Platinum Visa | C5: K PLUS | D5: Fuel-Susuki Ciaz | E5: 000/000 | F5: 44714 | G5: P | H5: 1400 | I5: =IF(My_Payment[[#This Row],[Payment_Code]]="S",My_Payment[[#This Row],[Total AMT]]/2,IF(My_Payment[[#This Row],[Payment_Code]]="P",My_Payment[[#This Row],[Total AMT]],0)) -> 1400 | J5: =IF(My_Payment[[#This Row],[Payment_Code]]="S",My_Payment[[#This Row],[Total AMT]]/2,IF(My_Payment[[#This Row],[Payment_Code]]="N",My_Payment[[#This Row],[Total AMT]],0)) -> 0
A6: 44664 | B6: Aeon Big C Platinum Visa | C6: K PLUS | D6: Sukishi BQ-Central Westgate | E6: 000/000 | F6: 44714 | G6: S | H6: 1197 | I6: =IF(My_Payment[[#This Row],[Payment_Code]]="S",My_Payment[[#This Row],[Total AMT]]/2,IF(My_Payment[[#This Row],[Payment_Code]]="P",My_Payment[[#This Row],[Total AMT]],0)) -> 598.5 | J6: =IF(My_Payment[[#This Row],[Payment_Code]]="S",My_Payment[[#This Row],[Total AMT]]/2,IF(My_Payment[[#This Row],[Payment_Code]]="N",My_Payment[[#This Row],[Total AMT]],0)) -> 598.5
A7: 44665 | B7: Aeon Big C Platinum Visa | C7: K PLUS | D7: BIG C-PETCHKASEM 2 | E7: 000/000 | F7: 44714 | G7: S | H7: 1846 | I7: 1078 | J7: 768
A8: 44667 | B8: Aeon Big C Platinum Visa | C8: K PLUS | D8: MINI BIG C | E8: 000/000 | F8: 44714 | G8: S | H8: 443.5 | I8: 280.5 | J8: 163
A9: 44675 | B9: Aeon Big C Platinum Visa | C9: K PLUS | D9: BIG C-PETCHKASEM | E9: 000/000 | F9: 44714 | G9: S | H9: 730.25 | I9: =IF(My_Payment[[#This Row],[Payment_Code]]="S",My_Payment[[#This Row],[Total AMT]]/2,IF(My_Payment[[#This Row],[Payment_Code]]="P",My_Payment[[#This Row],[Total AMT]],0)) -> 365.125 | J9: =IF(My_Payment[[#This Row],[Payment_Code]]="S",My_Payment[[#This Row],[Total AMT]]/2,IF(My_Payment[[#This Row],[Payment_Code]]="N",My_Payment[[#This Row],[Total AMT]],0)) -> 365.125
A10: 44691 | B10: Aeon Big C Platinum Visa | C10: K PLUS | D10: ST.Louis Hotpital | E10: 000/000 | F10: 44744 | G10: P | H10: 1035 | I10: =IF(My_Payment[[#This Row],[Payment_Code]]="S",My_Payment[[#This Row],[Total AMT]]/2,IF(My_Payment[[#This Row],[Payment_Code]]="P",My_Payment[[#This Row],[Total AMT]],0)) -> 1035 | J10: =IF(My_Payment[[#This Row],[Payment_Code]]="S",My_Payment[[#This Row],[Total AMT]]/2,IF(My_Payment[[#This Row],[Payment_Code]]="N",My_Payment[[#This Row],[Total AMT]],0)) -> 0
A11: 44696 | B11: Aeon Big C Platinum Visa | C11: K PLUS | D11: Super Sports-Central Westgate-ชุดว่ายน้ำ | E11: 000/000 | F11: 44744 | G11: S | H11: 979 | I11: =IF(My_Payment[[#This Row],[Payment_Code]]="S",My_Payment[[#This Row],[Total AMT]]/2,IF(My_Payment[[#This Row],[Payment_Code]]="P",My_Payment[[#This Row],[Total AMT]],0)) -> 489.5 | J11: =IF(My_Payment[[#This Row],[Payment_Code]]="S",My_Payment[[#This Row],[Total AMT]]/2,IF(My_Payment[[#This Row],[Payment_Code]]="N",My_Payment[[#This Row],[Total AMT]],0)) -> 489.5
A12: 44696 | B12: Aeon Big C Platinum Visa | C12: K PLUS | D12: MK Restaurant-Central Westgate | E12: 000/000 | F12: 44744 | G12: S | H12: 815 | I12: =IF(My_Payment[[#This Row],[Payment_Code]]="S",My_Payment[[#This Row],[Total AMT]]/2,IF(My_Payment[[#This Row],[Payment_Code]]="P",My_Payment[[#This Row],[Total AMT]],0)) -> 407.5 | J12: =IF(My_Payment[[#This Row],[Payment_Code]]="S",My_Payment[[#This Row],[Total AMT]]/2,IF(My_Payment[[#This Row],[Payment_Code]]="N",My_Payment[[#This Row],[Total AMT]],0)) -> 407.5
A13: 44724 | B13: Aeon Big C Platinum Visa | C13: K PLUS | D13: BIG C-PETCHKASEM 2 | E13: 000/000 | F13: 44775 | G13: S | H13: 1035.75 | I13: 740.125 | J13: 295.625
A14: 44731 | B14: Aeon Big C Platinum Visa | C14: K PLUS | D14: MINI BIG C | E14: 000/000 | F14: 44775 | G14: S | H14: 381 | I14: =IF(My_Payment[[#This Row],[Payment_Code]]="S",My_Payment[[#This Row],[Total AMT]]/2,IF(My_Payment[[#This Row],[Payment_Code]]="P",My_Payment[[#This Row],[Total AMT]],0)) -> 190.5 | J14: =IF(My_Payment[[#This Row],[Payment_Code]]="S",My_Payment[[#This Row],[Total AMT]]/2,IF(My_Payment[[#This Row],[Payment_Code]]="N",My_Payment[[#This Row],[Total AMT]],0)) -> 190.5
A15: 44748 | B15: Aeon Big C Platinum Visa | C15: K PLUS | D15: BIG C-PETCHKASEM 2 | E15: 000/000 | F15: 44775 | G15: S | H15: 584.75 | I15: =IF(My_Payment[[#This Row],[Payment_Code]]="S",My_Payment[[#This Row],[Total AMT]]/2,IF(My_Payment[[#This Row],[Payment_Code]]="P",My_Payment[[#This Row],[Total AMT]],0)) -> 292.375 | J15: =IF(My_Payment[[#This Row],[Payment_Code]]="S",My_Payment[[#This Row],[Total AMT]]/2,IF(My_Payment[[#This Row],[Payment_Code]]="N",My_Payment[[#This Row],[Total AMT]],0)) -> 292.375
A16: 44755 | B16: Aeon Big C Platinum Visa | C16: K PLUS | D16: DOOKKI KOREAN-Seacon Bangkae | E16: 000/000 | F16: 44806 | G16: S | H16: 598 | I16: =IF(My_Payment[[#This Row],[Payment_Code]]="S",My_Payment[[#This Row],[Total AMT]]/2,IF(My_Payment[[#This Row],[Payment_Code]]="P",My_Payment[[#This Row],[Total AMT]],0)) -> 299 | J16: =IF(My_Payment[[#This Row],[Payment_Code]]="S",My_Payment[[#This Row],[Total AMT]]/2,IF(My_Payment[[#This Row],[Payment_Code]]="N",My_Payment[[#This Row],[Total AMT]],0)) -> 299
A17: 44759 | B17: Aeon Big C Platinum Visa | C17: K PLUS | D17: BIG C-PETCHKASEM | E17: 000/000 | F17: 44806 | G17: S | H17: 336.5 | I17: =IF(My_Payment[[#This Row],[Payment_Code]]="S",My_Payment[[#This Row],[Total AMT]]/2,IF(My_Payment[[#This Row],[Payment_Code]]="P",My_Payment[[#This Row],[Total AMT]],0)) -> 168.25 | J17: =IF(My_Payment[[#This Row],[Payment_Code]]="S",My_Payment[[#This Row],[Total AMT]]/2,IF(My_Payment[[#This Row],[Payment_Code]]="N",My_Payment[[#This Row],[Total AMT]],0)) -> 168.25
A18: 44766 | B18: Aeon Big C Platinum Visa | C18: K PLUS | D18: BIG C-PETCHKASEM 2 | E18: 000/000 | F18: 44806 | G18: S | H18: 911.75 | I18: 415.75 | J18: 496
A19: 44780 | B19: Aeon Big C Platinum Visa | C19: K PLUS | D19: BIG C-PETCHKASEM 2 | E19: 000/000 | F19: 44806 | G19: S | H19: 757.5 | I19: 329.5 | J19: 428
A20: 44785 | B20: Aeon Big C Platinum Visa | C20: K PLUS | D20: BIG C-PETCHKASEM | E20: 000/000 | F20: 44836 | G20: S | H20: 1440.25 | I20: =IF(My_Payment[[#This Row],[Payment_Code]]="S",My_Payment[[#This Row],[Total AMT]]/2,IF(My_Payment[[#This Row],[Payment_Code]]="P",My_Payment[[#This Row],[Total AMT]],0)) -> 720.125 | J20: =IF(My_Payment[[#This Row],[Payment_Code]]="S",My_Payment[[#This Row],[Total AMT]]/2,IF(My_Payment[[#This Row],[Payment_Code]]="N",My_Payment[[#This Row],[Total AMT]],0)) -> 720.125
A21: 44793 | B21: Aeon Big C Platinum Visa | C21: K PLUS | D21: MINI BIG C | E21: 000/000 | F21: 44836 | G21: S | H21: 332.5 | I21: =IF(My_Payment[[#This Row],[Payment_Code]]="S",My_Payment[[#This Row],[Total AMT]]/2,IF(My_Payment[[#This Row],[Payment_Code]]="P",My_Payment[[#This Row],[Total AMT]],0)) -> 166.25 | J21: =IF(My_Payment[[#This Row],[Payment_Code]]="S",My_Payment[[#This Row],[Total AMT]]/2,IF(My_Payment[[#This Row],[Payment_Code]]="N",My_Payment[[#This Row],[Total AMT]],0)) -> 166.25
A22: 44822 | B22: Aeon Big C Platinum Visa | C22: K PLUS | D22: BIG C-PETCHKASEM 2 | E22: 000/000 | F22: 44867 | G22: S | H22: 1664.5 | I22: =IF(My_Payment[[#This Row],[Payment_Code]]="S",My_Payment[[#This Row],[Total AMT]]/2,IF(My_Payment[[#This Row],[Payment_Code]]="P",My_Payment[[#This Row],[Total AMT]],0)) -> 832.25 | J22: =IF(My_Payment[[#This Row],[Payment_Code]]="S",My_Payment[[#This Row],[Total AMT]]/2,IF(My_Payment[[#This Row],[Payment_Code]]="N",My_Payment[[#This Row],[Total AMT]],0)) -> 832.25
A23: 44847 | B23: Aeon Big C Platinum Visa | C23: K PLUS | D23: MINI BIG C | E23: 000/000 | F23: 44897 | G23: S | H23: 490.75 | I23: 259.75 | J23: 231
A24: 44847 | B24: Aeon Big C Platinum Visa | C24: K PLUS | D24: Fuel-Susuki Ciaz | E24: 000/000 | F24: 44897 | G24: P | H24: 1200 | I24: =IF(My_Payment[[#This Row],[Payment_Code]]="S",My_Payment[[#This Row],[Total AMT]]/2,IF(My_Payment[[#This Row],[Payment_Code]]="P",My_Payment[[#This Row],[Total AMT]],0)) -> 1200 | J24: =IF(My_Payment[[#This Row],[Payment_Code]]="S",My_Payment[[#This Row],[Total AMT]]/2,IF(My_Payment[[#This Row],[Payment_Code]]="N",My_Payment[[#This Row],[Total AMT]],0)) -> 0
A25: 44864 | B25: Aeon Big C Platinum Visa | C25: K PLUS | D25: BIG C-PETCHKASEM 2 | E25: 000/000 | F25: 44897 | G25: S | H25: 1941.25 | I25: 750.25 | J25: 1191
A26: 44733 | B26: Aeon M GEN Visa | C26: K PLUS | D26: MAJOR CINEPLEX-Jurassic World | E26: 000/000 | F26: 44775 | G26: P | H26: 539 | I26: =IF(My_Payment[[#This Row],[Payment_Code]]="S",My_Payment[[#This Row],[Total AMT]]/2,IF(My_Payment[[#This Row],[Payment_Code]]="P",My_Payment[[#This Row],[Total AMT]],0)) -> 539 | J26: =IF(My_Payment[[#This Row],[Payment_Code]]="S",My_Payment[[#This Row],[Total AMT]]/2,IF(My_Payment[[#This Row],[Payment_Code]]="N",My_Payment[[#This Row],[Total AMT]],0)) -> 0
A27: 44865 | B27: Aeon M GEN Visa | C27: K PLUS | D27: Annual Fee | E27: 000/000 | F27: 44897 | G27: P | H27: 214 | I27: =IF(My_Payment[[#This Row],[Payment_Code]]="S",My_Payment[[#This Row],[Total AMT]]/2,IF(My_Payment[[#This Row],[Payment_Code]]="P",My_Payment[[#This Row],[Total AMT]],0)) -> 214 | J27: =IF(My_Payment[[#This Row],[Payment_Code]]="S",My_Payment[[#This Row],[Total AMT]]/2,IF(My_Payment[[#This Row],[Payment_Code]]="N",My_Payment[[#This Row],[Total AMT]],0)) -> 0
A28: 44533 | B28: Central The 1 REDZ Credit Card | C28: KMA | D28: NETFLIX | E28: 000/000 | F28: 44583 | G28: P | H28: 419 | I28: =IF(My_Payment[[#This Row],[Payment_Code]]="S",My_Payment[[#This Row],[Total AMT]]/2,IF(My_Payment[[#This Row],[Payment_Code]]="P",My_Payment[[#This Row],[Total AMT]],0)) -> 419 | J28: =IF(My_Payment[[#This Row],[Payment_Code]]="S",My_Payment[[#This Row],[Total AMT]]/2,IF(My_Payment[[#This Row],[Payment_Code]]="N",My_Payment[[#This Row],[Total AMT]],0)) -> 0
A29: 44535 | B29: Central The 1 REDZ Credit Card | C29: KMA | D29: IKANO (Thailand)-IKIA Nontaburi | E29: 000/000 | F29: 44583 | G29: N | H29: 716 | I29: =IF(My_Payment[[#This Row],[Payment_Code]]="S",My_Payment[[#This Row],[Total AMT]]/2,IF(My_Payment[[#This Row],[Payment_Code]]="P",My_Payment[[#This Row],[Total AMT]],0)) -> 0 | J29: =IF(My_Payment[[#This Row],[Payment_Code]]="S",My_Payment[[#This Row],[Total AMT]]/2,IF(My_Payment[[#This Row],[Payment_Code]]="N",My_Payment[[#This Row],[Total AMT]],0)) -> 716
A30: 44540 | B30: Central The 1 REDZ Credit Card | C30: KMA | D30: Fuel-Susuki Ciaz | E30: 000/000 | F30: 44583 | G30: P | H30: 1060 | I30: =IF(My_Payment[[#This Row],[Payment_Code]]="S",My_Payment[[#This Row],[Total AMT]]/2,IF(My_Payment[[#This Row],[Payment_Code]]="P",My_Payment[[#This Row],[Total AMT]],0)) -> 1060 | J30: =IF(My_Payment[[#This Row],[Payment_Code]]="S",My_Payment[[#This Row],[Total AMT]]/2,IF(My_Payment[[#This Row],[Payment_Code]]="N",My_Payment[[#This Row],[Total AMT]],0)) -> 0
A31: 44563 | B31: Central The 1 REDZ Credit Card | C31: KMA | D31: THE MALL THAPHRA | E31: 000/000 | F31: 44614 | G31: N | H31: 1335 | I31: =IF(My_Payment[[#This Row],[Payment_Code]]="S",My_Payment[[#This Row],[Total AMT]]/2,IF(My_Payment[[#This Row],[Payment_Code]]="P",My_Payment[[#This Row],[Total AMT]],0)) -> 0 | J31: =IF(My_Payment[[#This Row],[Payment_Code]]="S",My_Payment[[#This Row],[Total AMT]]/2,IF(My_Payment[[#This Row],[Payment_Code]]="N",My_Payment[[#This Row],[Total AMT]],0)) -> 1335
A32: 44563 | B32: Central The 1 REDZ Credit Card | C32: KMA | D32: THE MALL THAPHRA | E32: 000/000 | F32: 44614 | G32: S | H32: 2632 | I32: =IF(My_Payment[[#This Row],[Payment_Code]]="S",My_Payment[[#This Row],[Total AMT]]/2,IF(My_Payment[[#This Row],[Payment_Code]]="P",My_Payment[[#This Row],[Total AMT]],0)) -> 1316 | J32: =IF(My_Payment[[#This Row],[Payment_Code]]="S",My_Payment[[#This Row],[Total AMT]]/2,IF(My_Payment[[#This Row],[Payment_Code]]="N",My_Payment[[#This Row],[Total AMT]],0)) -> 1316
A33: 44564 | B33: Central The 1 REDZ Credit Card | C33: KMA | D33: NETFLIX | E33: 000/000 | F33: 44614 | G33: P | H33: 419 | I33: =IF(My_Payment[[#This Row],[Payment_Code]]="S",My_Payment[[#This Row],[Total AMT]]/2,IF(My_Payment[[#This Row],[Payment_Code]]="P",My_Payment[[#This Row],[Total AMT]],0)) -> 419 | J33: =IF(My_Payment[[#This Row],[Payment_Code]]="S",My_Payment[[#This Row],[Total AMT]]/2,IF(My_Payment[[#This Row],[Payment_Code]]="N",My_Payment[[#This Row],[Total AMT]],0)) -> 0
A34: 44576 | B34: Central The 1 REDZ Credit Card | C34: KMA | D34: Shoppee Pay-Mask ปีใหม่ | E34: 000/000 | F34: 44614 | G34: P | H34: 280 | I34: =IF(My_Payment[[#This Row],[Payment_Code]]="S",My_Payment[[#This Row],[Total AMT]]/2,IF(My_Payment[[#This Row],[Payment_Code]]="P",My_Payment[[#This Row],[Total AMT]],0)) -> 280 | J34: =IF(My_Payment[[#This Row],[Payment_Code]]="S",My_Payment[[#This Row],[Total AMT]]/2,IF(My_Payment[[#This Row],[Payment_Code]]="N",My_Payment[[#This Row],[Total AMT]],0)) -> 0
A35: 44595 | B35: Central The 1 REDZ Credit Card | C35: KMA | D35: NETFLIX | E35: 000/000 | F35: 44642 | G35: P | H35: 419 | I35: =IF(My_Payment[[#This Row],[Payment_Code]]="S",My_Payment[[#This Row],[Total AMT]]/2,IF(My_Payment[[#This Row],[Payment_Code]]="P",My_Payment[[#This Row],[Total AMT]],0)) -> 419 | J35: =IF(My_Payment[[#This Row],[Payment_Code]]="S",My_Payment[[#This Row],[Total AMT]]/2,IF(My_Payment[[#This Row],[Payment_Code]]="N",My_Payment[[#This Row],[Total AMT]],0)) -> 0
A36: 44598 | B36: Central The 1 REDZ Credit Card | C36: KMA | D36: Steam Purchase | E36: 000/000 | F36: 44642 | G36: P | H36: 198.6 | I36: =IF(My_Payment[[#This Row],[Payment_Code]]="S",My_Payment[[#This Row],[Total AMT]]/2,IF(My_Payment[[#This Row],[Payment_Code]]="P",My_Payment[[#This Row],[Total AMT]],0)) -> 198.6 | J36: =IF(My_Payment[[#This Row],[Payment_Code]]="S",My_Payment[[#This Row],[Total AMT]]/2,IF(My_Payment[[#This Row],[Payment_Code]]="N",My_Payment[[#This Row],[Total AMT]],0)) -> 0
A37: 44598 | B37: Central The 1 REDZ Credit Card | C37: KMA | D37: A002-AIIZ Central Pinklao | E37: 000/000 | F37: 44642 | G37: P | H37: 450 | I37: =IF(My_Payment[[#This Row],[Payment_Code]]="S",My_Payment[[#This Row],[Total AMT]]/2,IF(My_Payment[[#This Row],[Payment_Code]]="P",My_Payment[[#This Row],[Total AMT]],0)) -> 450 | J37: =IF(My_Payment[[#This Row],[Payment_Code]]="S",My_Payment[[#This Row],[Total AMT]]/2,IF(My_Payment[[#This Row],[Payment_Code]]="N",My_Payment[[#This Row],[Total AMT]],0)) -> 0
... A49: 44657 | B49: Central The 1 REDZ Credit Card | C49: KMA | D49: Sukishi BQ-The Mall Bangkae | E49: 000/000 | F49: 44703 | G49: S | H49: 1390 | I49: =IF(My_Payment[[#This Row],[Payment_Code]]="S",My_Payment[[#This Row],[Total AMT]]/2,IF(My_Payment[[#This Row],[Payment_Code]]="P",My_Payment[[#This Row],[Total AMT]],0)) -> 695 | J49: =IF(My_Payment[[#This Row],[Payment_Code]]="S",My_Payment[[#This Row],[Total AMT]]/2,IF(My_Payment[[#This Row],[Payment_Code]]="N",My_Payment[[#This Row],[Total AMT]],0)) -> 695
A50: 44661 | B50: Central The 1 REDZ Credit Card | C50: KMA | D50: TOP Supermarket-Seacon Bangkae | E50: 000/000 | F50: 44703 | G50: S | H50: 529 | I50: 500 | J50: 29
A51: 44680 | B51: Central The 1 REDZ Credit Card | C51: KMA | D51: ST.Louis Hotpital | E51: 000/000 | F51: 44703 | G51: P | H51: 320 | I51: =IF(My_Payment[[#This Row],[Payment_Code]]="S",My_Payment[[#This Row],[Total AMT]]/2,IF(My_Payment[[#This Row],[Payment_Code]]="P",My_Payment[[#This Row],[Total AMT]],0)) -> 320 | J51: =IF(My_Payment[[#This Row],[Payment_Code]]="S",My_Payment[[#This Row],[Total AMT]]/2,IF(My_Payment[[#This Row],[Payment_Code]]="N",My_Payment[[#This Row],[Total AMT]],0)) -> 0
...

Sheet BigC Cal
B1: Golf | C1: Share | D1: Nink | E1: Total | G1: Golf | H1: Share | I1: Nink | J1: Total
E2: =SUM(B2:D2) -> 0 | G2: 40 | H2: 130 | J2: =SUM(G2:I2) -> 170
E3: =SUM(B3:D3) -> 0 | G3: 40 | H3: 30 | J3: =SUM(G3:I3) -> 70
E4: =SUM(B4:D4) -> 0 | G4: 224 | H4: 74 | J4: =SUM(G4:I4) -> 298
E5: =SUM(B5:D5) -> 0 | G5: 69 | H5: 45 | J5: =SUM(G5:I5) -> 114
E6: =SUM(B6:D6) -> 0 | G6: 44 | H6: 45 | J6: =SUM(G6:I6) -> 89
E7: =SUM(B7:D7) -> 0 | G7: 44 | H7: 74 | J7: =SUM(G7:I7) -> 118
E8: =SUM(B8:D8) -> 0 | G8: 44 | H8: 190 | J8: =SUM(G8:I8) -> 234
E9: =SUM(B9:D9) -> 0 | G9: 64 | H9: 132 | J9: =SUM(G9:I9) -> 196
E10: =SUM(B10:D10) -> 0 | G10: 56 | H10: -4 | J10: =SUM(G10:I10) -> 52
E11: =SUM(B11:D11) -> 0 | G11: -9 | H11: -4 | J11: =SUM(G11:I11) -> -13
E12: =SUM(B12:D12) -> 0 | J12: =SUM(G12:I12) -> 0
E13: =SUM(B13:D13) -> 0 | J13: =SUM(G13:I13) -> 0
E14: =SUM(B14:D14) -> 0 | J14: =SUM(G14:I14) -> 0
E15: =SUM(B15:D15) -> 0 | J15: =SUM(G15:I15) -> 0
E16: =SUM(B16:D16) -> 0 | J16: =SUM(G16:I16) -> 0
E17: =SUM(B17:D17) -> 0 | J17: =SUM(G17:I17) -> 0
E18: =SUM(B18:D18) -> 0 | J18: =SUM(G18:I18) -> 0
E19: =SUM(B19:D19) -> 0 | J19: =SUM(G19:I19) -> 0
E20: =SUM(B20:D20) -> 0 | J20: =SUM(G20:I20) -> 0
E21: =SUM(B21:D21) -> 0 | J21: =SUM(G21:I21) -> 0
E22: =SUM(B22:D22) -> 0 | J22: =SUM(G22:I22) -> 0
E23: =SUM(B23:D23) -> 0 | J23: =SUM(G23:I23) -> 0
... E39: =SUM(B39:D39) -> 0 | J39: =SUM(G39:I39) -> 0
A40: Total | B40: =SUM(B2:B39) -> 0 | C40: =SUM(C2:C39) -> 0 | D40: =SUM(D2:D39) -> 0 | E40: =SUM(E2:E39) -> 0 | G40: =SUM(G2:G39) -> 616 | H40: =SUM(H2:H39) -> 712 | I40: =SUM(I2:I39) -> 0 | J40: =SUM(J2:J39) -> 1328
A41: Discount | C41: -10 | E41: =SUM(B41:D41) -> -10 | H41: =-50-38.34 -> -88.34 | J41: =SUM(G41:I41) -> -88.34
A42: Total | B42: =SUM(B40:B41) -> 0 | C42: =SUM(C40:C41) -> -10 | D42: =SUM(D40:D41) -> 0 | E42: =SUM(E40:E41) -> -10 | G42: =SUM(G40:G41) -> 616 | H42: =SUM(H40:H41) -> 623.66 | I42: =SUM(I40:I41) -> 0 | J42: =SUM(J40:J41) -> 1239.66
A43: Allowcate | B43: =-C43*0.5 -> -5 | C43: =-C42 -> 10 | D43: =-C43*0.5 -> -5 | E43: =SUM(B43:D43) -> 0 | G43: =-H43*0.5 -> 311.83 | H43: =-H42 -> -623.66 | I43: =-H43*0.5 -> 311.83 | J43: =SUM(G43:I43) -> 0
A44: Total | B44: =SUM(B42:B43) -> -5 | C44: =SUM(C42:C43) -> 0 | D44: =SUM(D42:D43) -> -5 | E44: =SUM(B44:D44) -> -10 | G44: =SUM(G42:G43) -> 927.83 | H44: =SUM(H42:H43) -> 0 | I44: =SUM(I42:I43) -> 311.83 | J44: =SUM(G44:I44) -> 1239.66

Sheet Total AMT
B3: Sum of Total AMT | C3: Month
B4: Credit Card | C4: Jan | D4: Feb | E4: Mar | F4: Apr | G4: May | H4: Jun | I4: Jul | J4: Aug | K4: Sep | L4: Oct | M4: Nov | N4: Dec | O4: Grand Total
B5: Aeon Big C Platinum Visa | C5: 3177.72 | E5: 1175.64 | F5: 1407.47 | G5: 2690 | H5: 1694.16 | I5: 763.88 | O5: 10908.87
B6: Cash | C6: 528 | D6: 528 | E6: 528 | F6: 528 | G6: 528 | H6: 528 | I6: 528 | J6: 528 | K6: 528 | L6: 528 | M6: 528 | N6: 528 | O6: 6336
B7: Central The 1 REDZ Credit Card | C7: 1268 | D7: 1268 | E7: 1268 | F7: 1268 | G7: 1268 | H7: 1268 | I7: 1268 | J7: 1268 | K7: 1268 | L7: 1268 | M7: 1268 | N7: 1268 | O7: 15216
B8: Hompro Visa Platinum | C8: 2849 | D8: 5681.96 | E8: 3683.76 | F8: 4838.23 | G8: 7097.19 | H8: 4057.5 | I8: 5504.71 | O8: 33712.35
B9: KBANK Master Card Titanium | C9: 2239.2479 | D9: 2239.2479 | E9: 2239.2479 | F9: 2239.2479 | G9: 2239.2479 | H9: 2314.9959 | I9: 2345.9904 | J9: 2345.9904 | K9: 2345.9904 | L9: 2345.9904 | M9: 2345.9904 | N9: 2345.9904 | O9: 27587.177
B10: KBANK Shoppe Credit Card | C10: 2775.6 | D10: 2775.6 | E10: 2775.6 | F10: 2775.6 | G10: 2775.6 | H10: 378.1 | I10: 378.1 | J10: 378.1 | K10: 378.1 | L10: 378.1 | O10: 15768.5
B11: KTC-ROP Platinum Master Card | C11: 2517.8 | D11: 3240.67 | E11: 4771.26 | F11: 1243.8 | G11: 3093.8 | H11: 2566.8 | I11: 1243.8 | J11: 1243.8 | K11: 1243.8 | L11: 1243.8 | M11: 1243.8 | N11: 1243.8 | O11: 24896.93
B12: SpayLeter | C12: 3747.67 | D12: 938.66 | E12: 982 | F12: 422 | G12: 970 | H12: 995 | I12: 376.33 | J12: 521 | K12: 462.01 | L12: 193.66 | O12: 9608.33
B13: UOB Cash Plus | C13: 1360.83 | D13: 1360.83 | E13: 2628.41 | F13: 2628.41 | G13: 2628.41 | H13: 2628.41 | I13: 2628.42 | J13: 2628.42 | K13: 2628.42 | L13: 2628.42 | M13: 2628.42 | N13: 2628.42 | O13: 29005.82
B14: UOB One VISA | E14: 817.2 | F14: 12633.6 | G14: 4440.51 | H14: 4142.3 | I14: 1342.72 | J14: 2676.3 | K14: 2676.3 | L14: 2676.3 | M14: 2676.3 | N14: 2676.3 | O14: 36757.83
B15: Grand Total | C15: 20463.868 | D15: 18032.968 | E15: 20869.118 | F15: 29984.358 | G15: 27730.758 | H15: 20573.266 | I15: 16379.95 | J15: 11589.61 | K15: 11530.62 | L15: 11262.27 | M15: 10690.51 | N15: 10690.51 | O15: 209797.81

Sheet PK AMT
B4: Sum of PK_AMT | C4: Month
B5: Row Labels | C5: Jan | D5: Feb | E5: Mar | F5: Apr | G5: May | H5: Jun | I5: Jul | J5: Aug | K5: Sep | L5: Oct | M5: Nov | N5: Dec | O5: Grand Total
B6: (blank) | H6: 0 | O6: 0
B7: Aeon Big C Platinum Visa | C7: 1920.36 | E7: 587.82 | F7: 1111.74 | G7: 2690 | H7: 1215.83 | I7: 381.94 | O7: 7907.69
B8: Cash | C8: 269 | D8: 269 | E8: 269 | F8: 269 | G8: 269 | H8: 269 | I8: 268.5 | J8: 268.5 | K8: 268.5 | L8: 268.5 | M8: 268.5 | N8: 268.5 | O8: 3225
B9: Central The 1 REDZ Credit Card | C9: 969 | D9: 969 | E9: 969 | F9: 969 | G9: 969 | H9: 969 | I9: 969 | J9: 969 | K9: 969 | L9: 969 | M9: 969 | N9: 969 | O9: 11628
B10: Hompro Visa Platinum | C10: 2849 | D10: 4983.96 | E10: 3683.76 | F10: 4838.23 | G10: 6569.19 | H10: 3813.5 | I10: 3317.71 | O10: 30055.35
B11: KBANK Master Card Titanium | C11: 2239.2479 | D11: 2239.2479 | E11: 2239.2479 | F11: 2239.2479 | G11: 2239.2479 | H11: 2314.9959 | I11: 2345.9904 | J11: 2345.9904 | K11: 2345.9904 | L11: 2345.9904 | M11: 2345.9904 | N11: 2345.9904 | O11: 27587.177
B12: KBANK Shoppe Credit Card | C12: 2775.6 | D12: 2775.6 | E12: 2775.6 | F12: 2775.6 | G12: 2775.6 | H12: 378.1 | I12: 378.1 | J12: 378.1 | K12: 378.1 | L12: 378.1 | O12: 15768.5
B13: KTC-ROP Platinum Master Card | C13: 1880.8 | D13: 2391.735 | E13: 3007.53 | F13: 1243.8 | G13: 2168.8 | H13: 1905.3 | I13: 1243.8 | J13: 1243.8 | K13: 1243.8 | L13: 1243.8 | M13: 1243.8 | N13: 1243.8 | O13: 20060.765
B14: SpayLeter | C14: 3747.67 | D14: 938.66 | E14: 982 | F14: 422 | G14: 970 | H14: 995 | I14: 376.33 | J14: 521 | K14: 462.01 | L14: 193.66 | O14: 9608.33
B15: UOB Cash Plus | C15: 1360.83 | D15: 1360.83 | E15: 2628.41 | F15: 2628.41 | G15: 2628.41 | H15: 2628.41 | I15: 2628.42 | J15: 2628.42 | K15: 2628.42 | L15: 2628.42 | M15: 2628.42 | N15: 2628.42 | O15: 29005.82
B16: UOB One VISA | E16: 817.2 | F16: 12238.6 | G16: 1708.51 | H16: -3820.85 | I16: 763.57 | J16: 1338.15 | K16: 1338.15 | L16: 1338.15 | M16: 1338.15 | N16: 1338.15 | O16: 18397.78
B17: Grand Total | C17: 18011.508 | D17: 15928.033 | E17: 17959.568 | F17: 28735.628 | G17: 22987.758 | H17: 10668.286 | I17: 12673.36 | J17: 9692.9604 | K17: 9633.9704 | L17: 9365.6204 | M17: 8793.8604 | N17: 8793.8604 | O17: 173244.41

Sheet NC AMT
B4: Sum of NC_AMT | C4: Month
B5: Row Labels | C5: Jan | D5: Feb | E5: Mar | F5: Apr | G5: May | H5: Jun | I5: Jul | J5: Aug | K5: Sep | L5: Oct | M5: Nov | N5: Dec | O5: Grand Total
B6: (blank) | H6: 0 | O6: 0
B7: Aeon Big C Platinum Visa | C7: 1257.36 | E7: 587.82 | F7: 295.74 | G7: 0 | H7: 478.33 | I7: 381.94 | O7: 3001.19
B8: Cash | C8: 259 | D8: 259 | E8: 259 | F8: 259 | G8: 259 | H8: 259 | I8: 259.5 | J8: 259.5 | K8: 259.5 | L8: 259.5 | M8: 259.5 | N8: 259.5 | O8: 3111
B9: Central The 1 REDZ Credit Card | C9: 299 | D9: 299 | E9: 299 | F9: 299 | G9: 299 | H9: 299 | I9: 299 | J9: 299 | K9: 299 | L9: 299 | M9: 299 | N9: 299 | O9: 3588
B10: Hompro Visa Platinum | C10: 0 | D10: 698 | E10: 0 | F10: 0 | G10: 528 | H10: 244 | I10: 1355 | O10: 2825
B11: KBANK Master Card Titanium | C11: 0 | D11: 0 | E11: 0 | F11: 0 | G11: 0 | H11: 0 | I11: 0 | J11: 0 | K11: 0 | L11: 0 | M11: 0 | N11: 0 | O11: 0
B12: KBANK Shoppe Credit Card | C12: 0 | D12: 0 | E12: 0 | F12: 0 | G12: 0 | H12: 0 | I12: 0 | J12: 0 | K12: 0 | L12: 0 | O12: 0
B13: KTC-ROP Platinum Master Card | C13: 637 | D13: 848.935 | E13: 1763.73 | F13: 0 | G13: 925 | H13: 661.5 | I13: 0 | J13: 0 | K13: 0 | L13: 0 | M13: 0 | N13: 0 | O13: 4836.165
